Workbook

Sheet Project_Brief
A1: CAPSTONE PROJECT 4 — Agricultural Cooperative Production & Market Performance
A2: A farmer cooperative wants to evaluate crop production, input costs, sales, market channels, and farmer performance across districts.
A4: SECTION | B4: DETAIL
A5: Objectives
B6: Measure production and sales performance.
B7: Compare profitability across crops and districts.
B8: Recommend operational and market improvements.
A9: Required Tasks
B10: Excel: inspect the raw data; use appropriate formulas/functions (e.g., IF/IFS, COUNTIF(S), SUMIF(S), XLOOKUP or INDEX-MATCH) for at least 4 useful checks or calculations.
B11: Excel: create at least one PivotTable and PivotChart to perform an initial exploratory analysis.
B12: Power Query: clean the data, correct data types, remove duplicates where appropriate, handle missing values responsibly, standardize inconsistent text, and document important transformation steps.
B13: Data modelling: build appropriate relationships between the fact table and lookup/dimension tables; use a simple star-schema approach where appropriate.
B14: DAX: create at least 6 meaningful measures, including totals/counts, an average or rate, DIVIDE, and at least one CALCULATE-based measure.
B15: Power BI: build a professional interactive report with KPI cards, suitable comparison and trend visuals, filters/slicers, and clear titles.
B16: Analysis: write at least 5 evidence-based insights and 3 practical recommendations for management.
A17: Business Questions
B18: What are total production volume, sales revenue, and estimated gross margin?
B19: Which crops generate the highest revenue and gross margin?
B20: Which districts have the highest yield per acre?
B21: How do input costs vary by crop and district?
B22: Which market channels provide the highest average selling price?
B23: What proportion of harvested produce is sold versus lost/spoiled?
B24: Which farmer groups show the strongest performance?
B25: What seasonal patterns are visible in production and sales?
A26: Deliverables
B27: Cleaned Excel workbook or documented Excel analysis.
B28: Power BI (.pbix) report with data model, DAX measures, visuals, and slicers.
B29: One-page executive summary containing key findings and recommendations.

Sheet Crops
A1: Crop ID | B1: Crop
A2: C01 | B2: Maize
A3: C02 | B3: Rice
A4: C03 | B4: Tomato
A5: C04 | B5: Pepper
A6: C05 | B6: Soybean
A7: C06 | B7: Cassava

Sheet Districts
A1: District ID | B1: District
A2: D01 | B2: Ejura
A3: D02 | B3: Techiman
A4: D03 | B4: Tamale Metro
A5: D04 | B5: Kintampo
A6: D05 | B6: Hohoe

Sheet Farm_Records_RAW
A1: Farmer ID | B1: Record Date | C1: District ID | D1: Crop ID | E1: Acres Cultivated | F1: Harvest Quantity (kg) | G1: Post-Harvest Loss (kg) | H1: Quantity Sold (kg) | I1: Market Channel | J1: Selling Price/kg (GHS) | K1: Input Cost (GHS)
A2: F0128 | B2: 45853 | C2: D03 | D2: C01 | E2: 10.5 | F2: 21319.7 | G2: 2059.4 | H2: 19260.3 | I2: Wholesaler | J2: 3.44 | K2: 15514.19
A3: F0174 | B3: 45856 | C3: D05 | D3: C03 | E3: 8.9 | F3: 85227.8 | G3: 6234.1 | H3: 78993.7 | I3: Processor | J3: 7.38 | K3: 9897.9
A4: F0109 | B4: 45869 | C4: D04 | D4: C02 | E4: 14.6 | F4: 23614.4 | G4: 1146.9 | H4: 22467.5 | I4: Processor | J4: 5.02 | K4: 13966.62
A5: F0186 | B5: 45874 | C5: D03 | D5: C04 | E5: 5.3 | F5: 23649.2 | G5: 561.9 | H5: 23087.3 | I5: Farm Gate | J5: 10.29 | K5: 6689.27
A6: F0162 | B6: 45967 | C6: D05 | D6: C03 | E6: 6.5 | F6: 35848.5 | G6: 2534 | H6: 33314.5 | I6: Processor | J6: 6.85 | K6: 9552.4
A7: F0166 | B7: 45902 | C7: D01 | D7: C06 | E7: 10.7 | F7: 65606.6 | G7: 5542.3 | H7: 60064.3 | I7: Processor | J7: 2.16 | K7: 14864.02
A8: F0193 | B8: 46046 | C8: D03 | D8: C03 | E8: 2.6 | F8: 19136.5 | G8: 2597.2 | H8: 16539.3 | I8: Farm Gate | J8: 7.45 | K8: 2771.29
A9: F0066 | B9: 45911 | C9: D05 | D9: C02 | E9: 14.3 | F9: 38915.4 | G9: 3453.4 | H9: 35462 | I9: Wholesaler | J9: 5.31 | K9: 11122.26
A10: F0054 | B10: 46048 | C10: D02 | D10: C04 | E10: 1.9 | F10: 8780.3 | G10: 511.5 | H10: 8268.8 | I10: Farm Gate | J10: 8.15 | K10: 2517.24
A11: F0007 | B11: 45920 | C11: D02 | D11: C04 | E11: 5.6 | F11: 30015.3 | G11: 2728.7 | H11: 27286.6 | I11: Local Market | J11: 9.68 | K11: 4086.39
A12: F0033 | B12: 46146 | C12: D01 | D12: C05 | E12: 3.3 | F12: 3500.2 | G12: 252.2 | H12: 3248 | I12: Local Market | J12: 4.55 | K12: 5777.89
A13: F0093 | B13: 45948 | C13: D05 | D13: C02 | E13: 7.2 | F13: 19481.8 | G13: 2064.3 | H13: 17417.5 | I13: Farm Gate | J13: 6.95 | K13: 10411.07
... A506: F0098 | B506: 46060 | C506: D03 | D506: C04 | E506: 12.5 | F506: 64237.7 | G506: 9842.4 | H506: 54395.3 | I506: Processor | J506: 10.39 | K506: 18657.92

Sheet Sheet1
A3: Row Labels | B3: Sum of Gross Margin (GHS)
A4: Tomato | B4: 34941695
A5: Pepper | B5: 22972066
A6: Rice | B6: 8368911.2
A7: Cassava | B7: 7574519.4
A8: Soybean | B8: 3278962.5
A9: Maize | B9: 2454054.1
A10: Grand Total | B10: 79590209
A15: Sum of Gross Margin (GHS) | B15: Column Labels
A16: Row Labels | B16: Ejura | C16: Hohoe | D16: Kintampo | E16: Tamale Metro | F16: Techiman | G16: Grand Total
A17: Cassava | B17: 1774028.6 | C17: 1677267.1 | D17: 1213890.6 | E17: 1187733.8 | F17: 1721599.2 | G17: 7574519.4
A18: Maize | B18: 555403.72 | C18: 628495.44 | D18: 419478.07 | E18: 507515.04 | F18: 343161.85 | G18: 2454054.1
A19: Pepper | B19: 4104242.9 | C19: 4831071.9 | D19: 5409257.5 | E19: 5483754.3 | F19: 3143739.3 | G19: 22972066
A20: Rice | B20: 1512444.3 | C20: 2071210.7 | D20: 2435208.2 | E20: 1482025.1 | F20: 868022.96 | G20: 8368911.2
A21: Soybean | B21: 636142.18 | C21: 777595.34 | D21: 772065.21 | E21: 678657.24 | F21: 414502.57 | G21: 3278962.5
A22: Tomato | B22: 7231056.5 | C22: 7753969.1 | D22: 4047738.3 | E22: 9060742.6 | F22: 6848188.9 | G22: 34941695
A23: Grand Total | B23: 15813318 | C23: 17739609 | D23: 14297638 | E23: 18400428 | F23: 13339215 | G23: 79590209
A25: Crop Name | B25: Tomato
A27: Row Labels | B27: Average of Loss Rate % | C27: Average of Yield per Acre (kg) | D27: Average of Selling Price/kg (GHS) | E27: Yield % of Crop Average | F27: Selling Price% of Crop Average | G27: Margin per Acre (GHS) | H27: Margin per Acre %
A28: Ejura | B28: 0.099658849 | C28: 7730.2105 | D28: 6.6505263 | E28: =GETPIVOTDATA("Average of Yield per Acre (kg)",$A$27,"District Name","Ejura")/C50 -> 1.003278 | F28: =GETPIVOTDATA("Average of Selling Price/kg (GHS)",$A$27,"District Name","Ejura")/GETPIVOTDATA("Average of Selling Price/kg (GHS)",$A$27) -> 1.0046289 | G28: =SUMIFS(Farm_Records_Cleaned!$O$2:$O$501,Farm_Records_Cleaned!$D$2:$D$501,"C03",Farm_Records_Cleaned!$R$2:$R$501,"Ejura")/SUMIFS(Farm_Records_Cleaned!$E$2:$E$501,Farm_Records_Cleaned!$D$2:$D$501,"C03",Farm_Records_Cleaned!$R$2:$R$501,"Ejura") -> 43325.683 | H28: =G28/$D$49 -> 0.95673941
A29: Hohoe | B29: 0.085025813 | C29: 7942.7724 | D29: 6.88625 | E29: =GETPIVOTDATA("Average of Yield per Acre (kg)",$A$27,"District Name","Hohoe")/C50 -> 1.0308657 | F29: =GETPIVOTDATA("Average of Selling Price/kg (GHS)",$A$27,"District Name","Hohoe")/GETPIVOTDATA("Average of Selling Price/kg (GHS)",$A$27) -> 1.0402373 | G29: =SUMIFS(Farm_Records_Cleaned!$O$2:$O$501,Farm_Records_Cleaned!$D$2:$D$501,"C03",Farm_Records_Cleaned!$R$2:$R$501,"Hohoe")/SUMIFS(Farm_Records_Cleaned!$E$2:$E$501,Farm_Records_Cleaned!$D$2:$D$501,"C03",Farm_Records_Cleaned!$R$2:$R$501,"Hohoe") -> 49200.311 | H29: =G29/$D$49 -> 1.0864659
A30: Kintampo | B30: 0.10149992 | C30: 8025.8025 | D30: 6.662 | E30: =GETPIVOTDATA("Average of Yield per Acre (kg)",$A$27,"District Name","Kintampo")/C50 -> 1.0416418 | F30: =GETPIVOTDATA("Average of Selling Price/kg (GHS)",$A$27,"District Name","Kintampo")/GETPIVOTDATA("Average of Selling Price/kg (GHS)",$A$27) -> 1.0063621 | G30: =SUMIFS(Farm_Records_Cleaned!$O$2:$O$501,Farm_Records_Cleaned!$D$2:$D$501,"C03",Farm_Records_Cleaned!$R$2:$R$501,"Kintampo")/SUMIFS(Farm_Records_Cleaned!$E$2:$E$501,Farm_Records_Cleaned!$D$2:$D$501,"C03",Farm_Records_Cleaned!$R$2:$R$501,"Kintampo") -> 48130.063 | H30: =G30/$D$49 -> 1.0628321
A31: Tamale Metro | B31: 0.094726712 | C31: 7793.0589 | D31: 6.5345455 | E31: =GETPIVOTDATA("Average of Yield per Acre (kg)",$A$27,"District Name","Tamale Metro")/C50 -> 1.0114348 | F31: =GETPIVOTDATA("Average of Selling Price/kg (GHS)",$A$27,"District Name","Tamale Metro")/GETPIVOTDATA("Average of Selling Price/kg (GHS)",$A$27) -> 0.9871088 | G31: =SUMIFS(Farm_Records_Cleaned!$O$2:$O$501,Farm_Records_Cleaned!$D$2:$D$501,"C03",Farm_Records_Cleaned!$R$2:$R$501,"Tamale Metro")/SUMIFS(Farm_Records_Cleaned!$E$2:$E$501,Farm_Records_Cleaned!$D$2:$D$501,"C03",Farm_Records_Cleaned!$R$2:$R$501,"Tamale Metro") -> 46704.859 | H31: =G31/$D$49 -> 1.0313601
A32: Techiman | B32: 0.087132323 | C32: 7208.5456 | D32: 6.4415789 | E32: =GETPIVOTDATA("Average of Yield per Acre (kg)",$A$27,"District Name","Techiman")/C50 -> 0.93557283 | F32: =GETPIVOTDATA("Average of Selling Price/kg (GHS)",$A$27,"District Name","Techiman")/GETPIVOTDATA("Average of Selling Price/kg (GHS)",$A$27) -> 0.97306527 | G32: =SUMIFS(Farm_Records_Cleaned!$O$2:$O$501,Farm_Records_Cleaned!$D$2:$D$501,"C03",Farm_Records_Cleaned!$R$2:$R$501,"Techiman")/SUMIFS(Farm_Records_Cleaned!$E$2:$E$501,Farm_Records_Cleaned!$D$2:$D$501,"C03",Farm_Records_Cleaned!$R$2:$R$501,"Techiman") -> 40521.828 | H32: =G32/$D$49 -> 0.89482327
A33: Grand Total | B33: 0.093121304 | C33: 7704.954 | D33: 6.6198837
A35: Crop Name | B35: Pepper
A37: Row Labels | B37: Average of Loss Rate % | C37: Average of Yield per Acre (kg) | D37: Average of Selling Price/kg (GHS) | E37: Yield % of Crop Average | F37: Selling Price% of Crop Average | G37: Margin per Acre (GHS) | H37: Margin per Acre %
A38: Ejura | B38: 0.099628824 | C38: 4768.0051 | D38: 8.9263636 | E38: =GETPIVOTDATA("Average of Yield per Acre (kg)",$A$37,"District Name","Ejura")/C51 -> 0.94541567 | F38: =GETPIVOTDATA("Average of Selling Price/kg (GHS)",$A$37,"District Name","Ejura")/GETPIVOTDATA("Average of Selling Price/kg (GHS)",$A$37) -> 0.97808547 | G38: =SUMIFS(Farm_Records_Cleaned!$O$2:$O$501,Farm_Records_Cleaned!$D$2:$D$501,"C04",Farm_Records_Cleaned!$R$2:$R$501,"Ejura")/SUMIFS(Farm_Records_Cleaned!$E$2:$E$501,Farm_Records_Cleaned!$D$2:$D$501,"C04",Farm_Records_Cleaned!$R$2:$R$501,"Ejura") -> 39125.29 | H38: =G38/$D$50 -> 0.941341
A39: Hohoe | B39: 0.098471083 | C39: 5112.8539 | D39: 9.176875 | E39: =GETPIVOTDATA("Average of Yield per Acre (kg)",$A$37,"District Name","Hohoe")/C51 -> 1.0137934 | F39: =GETPIVOTDATA("Average of Selling Price/kg (GHS)",$A$37,"District Name","Hohoe")/GETPIVOTDATA("Average of Selling Price/kg (GHS)",$A$37) -> 1.0055347 | G39: =SUMIFS(Farm_Records_Cleaned!$O$2:$O$501,Farm_Records_Cleaned!$D$2:$D$501,"C04",Farm_Records_Cleaned!$R$2:$R$501,"Hohoe")/SUMIFS(Farm_Records_Cleaned!$E$2:$E$501,Farm_Records_Cleaned!$D$2:$D$501,"C04",Farm_Records_Cleaned!$R$2:$R$501,"Hohoe") -> 42303.606 | H39: =G39/$D$50 -> 1.0178102
A40: Kintampo | B40: 0.086355669 | C40: 4977.941 | D40: 8.9773684 | E40: =GETPIVOTDATA("Average of Yield per Acre (kg)",$A$37,"District Name","Kintampo")/C51 -> 0.98704246 | F40: =GETPIVOTDATA("Average of Selling Price/kg (GHS)",$A$37,"District Name","Kintampo")/GETPIVOTDATA("Average of Selling Price/kg (GHS)",$A$37) -> 0.9836742 | G40: =SUMIFS(Farm_Records_Cleaned!$O$2:$O$501,Farm_Records_Cleaned!$D$2:$D$501,"C04",Farm_Records_Cleaned!$R$2:$R$501,"Kintampo")/SUMIFS(Farm_Records_Cleaned!$E$2:$E$501,Farm_Records_Cleaned!$D$2:$D$501,"C04",Farm_Records_Cleaned!$R$2:$R$501,"Kintampo") -> 39570.282 | H40: =G40/$D$50 -> 0.95204736
A41: Tamale Metro | B41: 0.090723157 | C41: 5192.7472 | D41: 9.3147619 | E41: =GETPIVOTDATA("Average of Yield per Acre (kg)",$A$37,"District Name","Tamale Metro")/C51 -> 1.0296349 | F41: =GETPIVOTDATA("Average of Selling Price/kg (GHS)",$A$37)/GETPIVOTDATA("Average of Selling Price/kg (GHS)",$A$37) -> 1 | G41: =SUMIFS(Farm_Records_Cleaned!$O$2:$O$501,Farm_Records_Cleaned!$D$2:$D$501,"C04",Farm_Records_Cleaned!$R$2:$R$501,"Tamale Metro")/SUMIFS(Farm_Records_Cleaned!$E$2:$E$501,Farm_Records_Cleaned!$D$2:$D$501,"C04",Farm_Records_Cleaned!$R$2:$R$501,"Tamale Metro") -> 42908.876 | H41: =G41/$D$50 -> 1.0323728
A42: Techiman | B42: 0.07808321 | C42: 5045.1016 | D42: 9.153 | E42: =GETPIVOTDATA("Average of Yield per Acre (kg)",$A$37,"District Name","Techiman")/C51 -> 1.0003593 | F42: =GETPIVOTDATA("Average of Selling Price/kg (GHS)",$A$37,"District Name","Techiman")/GETPIVOTDATA("Average of Selling Price/kg (GHS)",$A$37) -> 1.0029186 | G42: =SUMIFS(Farm_Records_Cleaned!$O$2:$O$501,Farm_Records_Cleaned!$D$2:$D$501,"C04",Farm_Records_Cleaned!$R$2:$R$501,"Techiman")/SUMIFS(Farm_Records_Cleaned!$E$2:$E$501,Farm_Records_Cleaned!$D$2:$D$501,"C04",Farm_Records_Cleaned!$R$2:$R$501,"Techiman") -> 45495.504 | H42: =G42/$D$50 -> 1.0946062
A43: Grand Total | B43: 0.09088611 | C43: 5043.2897 | D43: 9.1263636
C47: overall average | D47: =AVERAGEIFS(Farm_Records_Cleaned!$J$2:$J$501,Farm_Records_Cleaned!$D$2:$D$501,"C03") -> 6.6198837
B48: Maize | C48: =AVERAGEIFS(Table1[Yield per Acre (kg)],Table1[Crop ID], "C01") -> 1709.9778
B49: Rice | C49: =AVERAGEIFS(Table1[Yield per Acre (kg)],Table1[Crop ID], "C02") -> 2277.8017 | D49: =SUMIFS(Farm_Records_Cleaned!$O$2:$O$501,Farm_Records_Cleaned!$D$2:$D$501,"C03")/SUMIFS(Farm_Records_Cleaned!$E$2:$E$501,Farm_Records_Cleaned!$D$2:$D$501,"C03") -> 45284.727
B50: Tomato | C50: =AVERAGEIFS(Table1[Yield per Acre (kg)],Table1[Crop ID], "C03") -> 7704.954 | D50: =SUMIFS(Farm_Records_Cleaned!$O$2:$O$501,Farm_Records_Cleaned!$D$2:$D$501,"C04")/SUMIFS(Farm_Records_Cleaned!$E$2:$E$501,Farm_Records_Cleaned!$D$2:$D$501,"C04") -> 41563.354
B51: Pepper | C51: =AVERAGEIFS(Table1[Yield per Acre (kg)],Table1[Crop ID], "C04") -> 5043.2897
B52: Soybean | C52: =AVERAGEIFS(Table1[Yield per Acre (kg)],Table1[Crop ID], "C05") -> 1508.6005
B53: Cassava | C53: =AVERAGEIFS(Table1[Yield per Acre (kg)],Table1[Crop ID], "C06") -> 6097.6687

Sheet Farm_Records_Cleaned
A1: Farmer ID | B1: Record Date | C1: District ID | D1: Crop ID | E1: Acres Cultivated | F1: Harvest Quantity (kg) | G1: Post-Harvest Loss (kg) | H1: Quantity Sold (kg) | I1: Market Channel | J1: Selling Price/kg (GHS) | K1: Input Cost (GHS) | L1: Yield per Acre (kg) | M1: Loss Rate % | N1: Revenue (GHS) | O1: Gross Margin (GHS) | P1: Flag | Q1: Crop Name | R1: District Name
A2: F0128 | B2: 45853 | C2: D03 | D2: C01 | E2: 10.5 | F2: 21319.7 | G2: 2059.4 | H2: 19260.3 | I2: Wholesaler | J2: 3.44 | K2: 15514.19 | L2: =F2/E2 -> 2030.4476 | M2: =G2/F2 -> 0.096596106 | N2: =H2*J2 -> 66255.432 | O2: =N2-K2 -> 50741.242 | P2: =IF(H2+G2>F2,"CHECK: Sold+Loss > Harvest","OK") -> OK | Q2: =INDEX(Crops!$B$2:$B$7,MATCH(D2,Crops!$A$2:$A$7,0)) -> Maize | R2: =INDEX(Districts!$B$2:$B$6,MATCH(C2,Districts!$A$2:$A$6,0)) -> Tamale Metro | T2: Count of Rice records | U2: =COUNTIFS($D$2:$D$501,"C02") -> 101
A3: F0174 | B3: 45856 | C3: D05 | D3: C03 | E3: 8.9 | F3: 85227.8 | G3: 6234.1 | H3: 78993.7 | I3: Processor | J3: 7.38 | K3: 9897.9 | L3: =F3/E3 -> 9576.1573 | M3: =G3/F3 -> 0.073146321 | N3: =H3*J3 -> 582973.51 | O3: =N3-K3 -> 573075.61 | P3: =IF(H3+G3>F3,"CHECK: Sold+Loss > Harvest","OK") -> OK | Q3: =INDEX(Crops!$B$2:$B$7,MATCH(D3,Crops!$A$2:$A$7,0)) -> Tomato | R3: =INDEX(Districts!$B$2:$B$6,MATCH(C3,Districts!$A$2:$A$6,0)) -> Hohoe | T3: Count of Tomato records | U3: =COUNTIFS($D$2:$D$501,"C03") -> 86
A4: F0109 | B4: 45869 | C4: D04 | D4: C02 | E4: 14.6 | F4: 23614.4 | G4: 1146.9 | H4: 22467.5 | I4: Processor | J4: 5.02 | K4: 13966.62 | L4: =F4/E4 -> 1617.4247 | M4: =G4/F4 -> 0.048567823 | N4: =H4*J4 -> 112786.85 | O4: =N4-K4 -> 98820.23 | P4: =IF(H4+G4>F4,"CHECK: Sold+Loss > Harvest","OK") -> OK | Q4: =INDEX(Crops!$B$2:$B$7,MATCH(D4,Crops!$A$2:$A$7,0)) -> Rice | R4: =INDEX(Districts!$B$2:$B$6,MATCH(C4,Districts!$A$2:$A$6,0)) -> Kintampo | T4: Count of Cassava records | U4: =COUNTIFS($D$2:$D$501,"C06") -> 82
A5: F0186 | B5: 45874 | C5: D03 | D5: C04 | E5: 5.3 | F5: 23649.2 | G5: 561.9 | H5: 23087.3 | I5: Farm Gate | J5: 10.29 | K5: 6689.27 | L5: =F5/E5 -> 4462.1132 | M5: =G5/F5 -> 0.023759789 | N5: =H5*J5 -> 237568.32 | O5: =N5-K5 -> 230879.05 | P5: =IF(H5+G5>F5,"CHECK: Sold+Loss > Harvest","OK") -> OK | Q5: =INDEX(Crops!$B$2:$B$7,MATCH(D5,Crops!$A$2:$A$7,0)) -> Pepper | R5: =INDEX(Districts!$B$2:$B$6,MATCH(C5,Districts!$A$2:$A$6,0)) -> Tamale Metro | T5: Count of Soybean records | U5: =COUNTIFS($D$2:$D$501,"C05") -> 78
A6: F0162 | B6: 45967 | C6: D05 | D6: C03 | E6: 6.5 | F6: 35848.5 | G6: 2534 | H6: 33314.5 | I6: Processor | J6: 6.85 | K6: 9552.4 | L6: =F6/E6 -> 5515.1538 | M6: =G6/F6 -> 0.070686361 | N6: =H6*J6 -> 228204.32 | O6: =N6-K6 -> 218651.92 | P6: =IF(H6+G6>F6,"CHECK: Sold+Loss > Harvest","OK") -> OK | Q6: =INDEX(Crops!$B$2:$B$7,MATCH(D6,Crops!$A$2:$A$7,0)) -> Tomato | R6: =INDEX(Districts!$B$2:$B$6,MATCH(C6,Districts!$A$2:$A$6,0)) -> Hohoe | T6: Count of Pepper records | U6: =COUNTIFS($D$2:$D$501,"C04") -> 77
A7: F0166 | B7: 45902 | C7: D01 | D7: C06 | E7: 10.7 | F7: 65606.6 | G7: 5542.3 | H7: 60064.3 | I7: Processor | J7: 2.16 | K7: 14864.02 | L7: =F7/E7 -> 6131.4579 | M7: =G7/F7 -> 0.084477781 | N7: =H7*J7 -> 129738.89 | O7: =N7-K7 -> 114874.87 | P7: =IF(H7+G7>F7,"CHECK: Sold+Loss > Harvest","OK") -> OK | Q7: =INDEX(Crops!$B$2:$B$7,MATCH(D7,Crops!$A$2:$A$7,0)) -> Cassava | R7: =INDEX(Districts!$B$2:$B$6,MATCH(C7,Districts!$A$2:$A$6,0)) -> Ejura | T7: Count of Maize records | U7: =COUNTIFS($D$2:$D$501,"C01") -> 76
A8: F0193 | B8: 46046 | C8: D03 | D8: C03 | E8: 2.6 | F8: 19136.5 | G8: 2597.2 | H8: 16539.3 | I8: Farm Gate | J8: 7.45 | K8: 2771.29 | L8: =F8/E8 -> 7360.1923 | M8: =G8/F8 -> 0.1357197 | N8: =H8*J8 -> 123217.79 | O8: =N8-K8 -> 120446.5 | P8: =IF(H8+G8>F8,"CHECK: Sold+Loss > Harvest","OK") -> OK | Q8: =INDEX(Crops!$B$2:$B$7,MATCH(D8,Crops!$A$2:$A$7,0)) -> Tomato | R8: =INDEX(Districts!$B$2:$B$6,MATCH(C8,Districts!$A$2:$A$6,0)) -> Tamale Metro
A9: F0066 | B9: 45911 | C9: D05 | D9: C02 | E9: 14.3 | F9: 38915.4 | G9: 3453.4 | H9: 35462 | I9: Wholesaler | J9: 5.31 | K9: 11122.26 | L9: =F9/E9 -> 2721.3566 | M9: =G9/F9 -> 0.088741218 | N9: =H9*J9 -> 188303.22 | O9: =N9-K9 -> 177180.96 | P9: =IF(H9+G9>F9,"CHECK: Sold+Loss > Harvest","OK") -> OK | Q9: =INDEX(Crops!$B$2:$B$7,MATCH(D9,Crops!$A$2:$A$7,0)) -> Rice | R9: =INDEX(Districts!$B$2:$B$6,MATCH(C9,Districts!$A$2:$A$6,0)) -> Hohoe
A10: F0054 | B10: 46048 | C10: D02 | D10: C04 | E10: 1.9 | F10: 8780.3 | G10: 511.5 | H10: 8268.8 | I10: Farm Gate | J10: 8.15 | K10: 2517.24 | L10: =F10/E10 -> 4621.2105 | M10: =G10/F10 -> 0.058255413 | N10: =H10*J10 -> 67390.72 | O10: =N10-K10 -> 64873.48 | P10: =IF(H10+G10>F10,"CHECK: Sold+Loss > Harvest","OK") -> OK | Q10: =INDEX(Crops!$B$2:$B$7,MATCH(D10,Crops!$A$2:$A$7,0)) -> Pepper | R10: =INDEX(Districts!$B$2:$B$6,MATCH(C10,Districts!$A$2:$A$6,0)) -> Techiman
A11: F0007 | B11: 45920 | C11: D02 | D11: C04 | E11: 5.6 | F11: 30015.3 | G11: 2728.7 | H11: 27286.6 | I11: Local Market | J11: 9.68 | K11: 4086.39 | L11: =F11/E11 -> 5359.875 | M11: =G11/F11 -> 0.090910302 | N11: =H11*J11 -> 264134.29 | O11: =N11-K11 -> 260047.9 | P11: =IF(H11+G11>F11,"CHECK: Sold+Loss > Harvest","OK") -> OK | Q11: =INDEX(Crops!$B$2:$B$7,MATCH(D11,Crops!$A$2:$A$7,0)) -> Pepper | R11: =INDEX(Districts!$B$2:$B$6,MATCH(C11,Districts!$A$2:$A$6,0)) -> Techiman | T11: Total revenue for Tomato | U11: =SUMIFS($N$2:$N$501,$D$2:$D$501,"C03") -> 35966209
A12: F0033 | B12: 46146 | C12: D01 | D12: C05 | E12: 3.3 | F12: 3500.2 | G12: 252.2 | H12: 3248 | I12: Local Market | J12: 4.55 | K12: 5777.89 | L12: =F12/E12 -> 1060.6667 | M12: =G12/F12 -> 0.072053026 | N12: =H12*J12 -> 14778.4 | O12: =N12-K12 -> 9000.51 | P12: =IF(H12+G12>F12,"CHECK: Sold+Loss > Harvest","OK") -> OK | Q12: =INDEX(Crops!$B$2:$B$7,MATCH(D12,Crops!$A$2:$A$7,0)) -> Soybean | R12: =INDEX(Districts!$B$2:$B$6,MATCH(C12,Districts!$A$2:$A$6,0)) -> Ejura | T12: Total revenue for Pepper | U12: =SUMIFS($N$2:$N$501,$D$2:$D$501,"C04") -> 23685224
A13: F0093 | B13: 45948 | C13: D05 | D13: C02 | E13: 7.2 | F13: 19481.8 | G13: 2064.3 | H13: 17417.5 | I13: Farm Gate | J13: 6.95 | K13: 10411.07 | L13: =F13/E13 -> 2705.8056 | M13: =G13/F13 -> 0.10596043 | N13: =H13*J13 -> 121051.62 | O13: =N13-K13 -> 110640.55 | P13: =IF(H13+G13>F13,"CHECK: Sold+Loss > Harvest","OK") -> OK | Q13: =INDEX(Crops!$B$2:$B$7,MATCH(D13,Crops!$A$2:$A$7,0)) -> Rice | R13: =INDEX(Districts!$B$2:$B$6,MATCH(C13,Districts!$A$2:$A$6,0)) -> Hohoe | T13: Total revenue for Rice | U13: =SUMIFS($N$2:$N$501,$D$2:$D$501,"C02") -> 9296537
A14: F0176 | B14: 45867 | C14: D03 | D14: C03 | E14: 10.7 | F14: 107180.5 | G14: 8191.9 | H14: 98988.6 | I14: Farm Gate | J14: 7.72 | K14: 17232.07 | L14: =F14/E14 -> 10016.869 | M14: =G14/F14 -> 0.076430881 | N14: =H14*J14 -> 764191.99 | O14: =N14-K14 -> 746959.92 | P14: =IF(H14+G14>F14,"CHECK: Sold+Loss > Harvest","OK") -> OK | Q14: =INDEX(Crops!$B$2:$B$7,MATCH(D14,Crops!$A$2:$A$7,0)) -> Tomato | R14: =INDEX(Districts!$B$2:$B$6,MATCH(C14,Districts!$A$2:$A$6,0)) -> Tamale Metro | T14: Total revenue for Cassava | U14: =SUMIFS($N$2:$N$501,$D$2:$D$501,"C06") -> 8291839.4
A15: F0213 | B15: 46083 | C15: D02 | D15: C05 | E15: 12 | F15: 21845.4 | G15: 1774.4 | H15: 20071 | I15: Local Market | J15: 4.21 | K15: 18488.91 | L15: =F15/E15 -> 1820.45 | M15: =G15/F15 -> 0.081225338 | N15: =H15*J15 -> 84498.91 | O15: =N15-K15 -> 66010 | P15: =IF(H15+G15>F15,"CHECK: Sold+Loss > Harvest","OK") -> OK | Q15: =INDEX(Crops!$B$2:$B$7,MATCH(D15,Crops!$A$2:$A$7,0)) -> Soybean | R15: =INDEX(Districts!$B$2:$B$6,MATCH(C15,Districts!$A$2:$A$6,0)) -> Techiman | T15: Total revenue for Soybean | U15: =SUMIFS($N$2:$N$501,$D$2:$D$501,"C05") -> 4099255.6
A16: F0172 | B16: 46114 | C16: D05 | D16: C02 | E16: 2.1 | F16: 3757.2 | G16: 552.7 | H16: 3204.5 | I16: Local Market | J16: 5.31 | K16: 3041.08 | L16: =F16/E16 -> 1789.1429 | M16: =G16/F16 -> 0.14710423 | N16: =H16*J16 -> 17015.895 | O16: =N16-K16 -> 13974.815 | P16: =IF(H16+G16>F16,"CHECK: Sold+Loss > Harvest","OK") -> OK | Q16: =INDEX(Crops!$B$2:$B$7,MATCH(D16,Crops!$A$2:$A$7,0)) -> Rice | R16: =INDEX(Districts!$B$2:$B$6,MATCH(C16,Districts!$A$2:$A$6,0)) -> Hohoe | T16: Total revenue for Maize | U16: =SUMIFS($N$2:$N$501,$D$2:$D$501,"C01") -> 3210206.1
A17: F0164 | B17: 45961 | C17: D02 | D17: C02 | E17: 2.2 | F17: 5789.3 | G17: 563.3 | H17: 5226 | I17: Processor | J17: 5.96 | K17: 2220.58 | L17: =F17/E17 -> 2631.5 | M17: =G17/F17 -> 0.097300192 | N17: =H17*J17 -> 31146.96 | O17: =N17-K17 -> 28926.38 | P17: =IF(H17+G17>F17,"CHECK: Sold+Loss > Harvest","OK") -> OK | Q17: =INDEX(Crops!$B$2:$B$7,MATCH(D17,Crops!$A$2:$A$7,0)) -> Rice | R17: =INDEX(Districts!$B$2:$B$6,MATCH(C17,Districts!$A$2:$A$6,0)) -> Techiman
A18: F0042 | B18: 46057 | C18: D04 | D18: C03 | E18: 13.6 | F18: 115504.3 | G18: 16132.6 | H18: 99371.7 | I18: Farm Gate | J18: 7.63 | K18: 20302.55 | L18: =F18/E18 -> 8492.9632 | M18: =G18/F18 -> 0.13967099 | N18: =H18*J18 -> 758206.07 | O18: =N18-K18 -> 737903.52 | P18: =IF(H18+G18>F18,"CHECK: Sold+Loss > Harvest","OK") -> OK | Q18: =INDEX(Crops!$B$2:$B$7,MATCH(D18,Crops!$A$2:$A$7,0)) -> Tomato | R18: =INDEX(Districts!$B$2:$B$6,MATCH(C18,Districts!$A$2:$A$6,0)) -> Kintampo | T18: Total Input Cost by crop
A19: F0136 | B19: 45862 | C19: D01 | D19: C03 | E19: 12.9 | F19: 92115.3 | G19: 2849.8 | H19: 89265.5 | I19: Processor | J19: 5.91 | K19: 15299.64 | L19: =F19/E19 -> 7140.7209 | M19: =G19/F19 -> 0.030937314 | N19: =H19*J19 -> 527559.1 | O19: =N19-K19 -> 512259.46 | P19: =IF(H19+G19>F19,"CHECK: Sold+Loss > Harvest","OK") -> OK | Q19: =INDEX(Crops!$B$2:$B$7,MATCH(D19,Crops!$A$2:$A$7,0)) -> Tomato | R19: =INDEX(Districts!$B$2:$B$6,MATCH(C19,Districts!$A$2:$A$6,0)) -> Ejura | T19: Tomato | U19: =SUMIFS($K$2:$K$501,$D$2:$D$501,"C03") -> 1024514
A20: F0190 | B20: 46060 | C20: D03 | D20: C05 | E20: 7.8 | F20: 12493.9 | G20: 441.2 | H20: 12052.7 | I20: Processor | J20: 4.87 | K20: 12082.17 | L20: =F20/E20 -> 1601.7821 | M20: =G20/F20 -> 0.035313233 | N20: =H20*J20 -> 58696.649 | O20: =N20-K20 -> 46614.479 | P20: =IF(H20+G20>F20,"CHECK: Sold+Loss > Harvest","OK") -> OK | Q20: =INDEX(Crops!$B$2:$B$7,MATCH(D20,Crops!$A$2:$A$7,0)) -> Soybean | R20: =INDEX(Districts!$B$2:$B$6,MATCH(C20,Districts!$A$2:$A$6,0)) -> Tamale Metro | T20: Rice | U20: =SUMIFS($K$2:$K$501,$D$2:$D$501,"C02") -> 927625.84
A21: F0002 | B21: 45848 | C21: D01 | D21: C05 | E21: 6.7 | F21: 13190.3 | G21: 439.3 | H21: 12751 | I21: Wholesaler | J21: 5.22 | K21: 5008.09 | L21: =F21/E21 -> 1968.7015 | M21: =G21/F21 -> 0.033304777 | N21: =H21*J21 -> 66560.22 | O21: =N21-K21 -> 61552.13 | P21: =IF(H21+G21>F21,"CHECK: Sold+Loss > Harvest","OK") -> OK | Q21: =INDEX(Crops!$B$2:$B$7,MATCH(D21,Crops!$A$2:$A$7,0)) -> Soybean | R21: =INDEX(Districts!$B$2:$B$6,MATCH(C21,Districts!$A$2:$A$6,0)) -> Ejura | T21: Soybean | U21: =SUMIFS($K$2:$K$501,$D$2:$D$501,"C05") -> 820293.05
A22: F0038 | B22: 46124 | C22: D05 | D22: C04 | E22: 3.8 | F22: 19524.8 | G22: 2536.8 | H22: 16988 | I22: Farm Gate | J22: 8.31 | K22: 6059.77 | L22: =F22/E22 -> 5138.1053 | M22: =G22/F22 -> 0.12992707 | N22: =H22*J22 -> 141170.28 | O22: =N22-K22 -> 135110.51 | P22: =IF(H22+G22>F22,"CHECK: Sold+Loss > Harvest","OK") -> OK | Q22: =INDEX(Crops!$B$2:$B$7,MATCH(D22,Crops!$A$2:$A$7,0)) -> Pepper | R22: =INDEX(Districts!$B$2:$B$6,MATCH(C22,Districts!$A$2:$A$6,0)) -> Hohoe | T22: Maize | U22: =SUMIFS($K$2:$K$501,$D$2:$D$501,"C01") -> 756151.94
A23: F0092 | B23: 46179 | C23: D04 | D23: C06 | E23: 7 | F23: 53598.9 | G23: 4311.7 | H23: 49287.2 | I23: Farm Gate | J23: 2.69 | K23: 6886.83 | L23: =F23/E23 -> 7656.9857 | M23: =G23/F23 -> 0.080443815 | N23: =H23*J23 -> 132582.57 | O23: =N23-K23 -> 125695.74 | P23: =IF(H23+G23>F23,"CHECK: Sold+Loss > Harvest","OK") -> OK | Q23: =INDEX(Crops!$B$2:$B$7,MATCH(D23,Crops!$A$2:$A$7,0)) -> Cassava | R23: =INDEX(Districts!$B$2:$B$6,MATCH(C23,Districts!$A$2:$A$6,0)) -> Kintampo | T23: Cassava | U23: =SUMIFS($K$2:$K$501,$D$2:$D$501,"C06") -> 717320
A24: F0154 | B24: 46018 | C24: D05 | D24: C06 | E24: 7.3 | F24: 56037.4 | G24: 7311.7 | H24: 48725.7 | I24: Processor | J24: 2.27 | K24: 8292.62 | L24: =F24/E24 -> 7676.3562 | M24: =G24/F24 -> 0.13047893 | N24: =H24*J24 -> 110607.34 | O24: =N24-K24 -> 102314.72 | P24: =IF(H24+G24>F24,"CHECK: Sold+Loss > Harvest","OK") -> OK | Q24: =INDEX(Crops!$B$2:$B$7,MATCH(D24,Crops!$A$2:$A$7,0)) -> Cassava | R24: =INDEX(Districts!$B$2:$B$6,MATCH(C24,Districts!$A$2:$A$6,0)) -> Hohoe | T24: Pepper | U24: =SUMIFS($K$2:$K$501,$D$2:$D$501,"C04") -> 713158.34
A25: F0140 | B25: 45894 | C25: D03 | D25: C02 | E25: 8.5 | F25: 20220.9 | G25: 1942.1 | H25: 18278.8 | I25: Processor | J25: 6.82 | K25: 13626.91 | L25: =F25/E25 -> 2378.9294 | M25: =G25/F25 -> 0.096044192 | N25: =H25*J25 -> 124661.42 | O25: =N25-K25 -> 111034.51 | P25: =IF(H25+G25>F25,"CHECK: Sold+Loss > Harvest","OK") -> OK | Q25: =INDEX(Crops!$B$2:$B$7,MATCH(D25,Crops!$A$2:$A$7,0)) -> Rice | R25: =INDEX(Districts!$B$2:$B$6,MATCH(C25,Districts!$A$2:$A$6,0)) -> Tamale Metro
A26: F0064 | B26: 46049 | C26: D03 | D26: C01 | E26: 8.9 | F26: 14528.1 | G26: 1525.2 | H26: 13002.9 | I26: Local Market | J26: 3.79 | K26: 12986.23 | L26: =F26/E26 -> 1632.3708 | M26: =G26/F26 -> 0.10498276 | N26: =H26*J26 -> 49280.991 | O26: =N26-K26 -> 36294.761 | P26: =IF(H26+G26>F26,"CHECK: Sold+Loss > Harvest","OK") -> OK | Q26: =INDEX(Crops!$B$2:$B$7,MATCH(D26,Crops!$A$2:$A$7,0)) -> Maize | R26: =INDEX(Districts!$B$2:$B$6,MATCH(C26,Districts!$A$2:$A$6,0)) -> Tamale Metro | T26: Gross Margin by crop | V26: % of Revenue
A27: F0012 | B27: 46131 | C27: D04 | D27: C01 | E27: 15 | F27: 29249.8 | G27: 1250.8 | H27: 27999 | I27: Wholesaler | J27: 2.99 | K27: 12276.47 | L27: =F27/E27 -> 1949.9867 | M27: =G27/F27 -> 0.042762686 | N27: =H27*J27 -> 83717.01 | O27: =N27-K27 -> 71440.54 | P27: =IF(H27+G27>F27,"CHECK: Sold+Loss > Harvest","OK") -> OK | Q27: =INDEX(Crops!$B$2:$B$7,MATCH(D27,Crops!$A$2:$A$7,0)) -> Maize | R27: =INDEX(Districts!$B$2:$B$6,MATCH(C27,Districts!$A$2:$A$6,0)) -> Kintampo | T27: Tomato | U27: =SUMIFS($O$2:$O$501,$D$2:$D$501,"C03") -> 34941695 | V27: =(U11 - U19) / U11 -> 0.97151454
A28: F0098 | B28: 46013 | C28: D02 | D28: C02 | E28: 6 | F28: 11042.2 | G28: 863.5 | H28: 10178.7 | I28: Local Market | J28: 4.97 | K28: 5788.26 | L28: =F28/E28 -> 1840.3667 | M28: =G28/F28 -> 0.078199996 | N28: =H28*J28 -> 50588.139 | O28: =N28-K28 -> 44799.879 | P28: =IF(H28+G28>F28,"CHECK: Sold+Loss > Harvest","OK") -> OK | Q28: =INDEX(Crops!$B$2:$B$7,MATCH(D28,Crops!$A$2:$A$7,0)) -> Rice | R28: =INDEX(Districts!$B$2:$B$6,MATCH(C28,Districts!$A$2:$A$6,0)) -> Techiman | T28: Pepper | U28: =SUMIFS($O$2:$O$501,$D$2:$D$501,"C04") -> 22972066 | V28: =(U12 - U24) / U12 -> 0.96989016
A29: F0063 | B29: 46044 | C29: D03 | D29: C02 | E29: 12.9 | F29: 26760 | G29: 3173.3 | H29: 23586.7 | I29: Farm Gate | J29: 6.48 | K29: 15846.65 | L29: =F29/E29 -> 2074.4186 | M29: =G29/F29 -> 0.11858371 | N29: =H29*J29 -> 152841.82 | O29: =N29-K29 -> 136995.17 | P29: =IF(H29+G29>F29,"CHECK: Sold+Loss > Harvest","OK") -> OK | Q29: =INDEX(Crops!$B$2:$B$7,MATCH(D29,Crops!$A$2:$A$7,0)) -> Rice | R29: =INDEX(Districts!$B$2:$B$6,MATCH(C29,Districts!$A$2:$A$6,0)) -> Tamale Metro | T29: Rice | U29: =SUMIFS($O$2:$O$501,$D$2:$D$501,"C02") -> 8368911.2 | V29: =(U13 - U20) / U13 -> 0.90021813
A30: F0049 | B30: 46153 | C30: D05 | D30: C05 | E30: 13.4 | F30: 14163.1 | G30: 2072.1 | H30: 12091 | I30: Wholesaler | J30: 5.36 | K30: 12492.51 | L30: =F30/E30 -> 1056.9478 | M30: =G30/F30 -> 0.14630272 | N30: =H30*J30 -> 64807.76 | O30: =N30-K30 -> 52315.25 | P30: =IF(H30+G30>F30,"CHECK: Sold+Loss > Harvest","OK") -> OK | Q30: =INDEX(Crops!$B$2:$B$7,MATCH(D30,Crops!$A$2:$A$7,0)) -> Soybean | R30: =INDEX(Districts!$B$2:$B$6,MATCH(C30,Districts!$A$2:$A$6,0)) -> Hohoe | T30: Cassava | U30: =SUMIFS($O$2:$O$501,$D$2:$D$501,"C06") -> 7574519.4 | V30: =(U14 - U23) / U14 -> 0.91349085
A31: F0143 | B31: 45912 | C31: D03 | D31: C04 | E31: 1.9 | F31: 12182.2 | G31: 910 | H31: 11272.2 | I31: Wholesaler | J31: 9.78 | K31: 1926.57 | L31: =F31/E31 -> 6411.6842 | M31: =G31/F31 -> 0.074699151 | N31: =H31*J31 -> 110242.12 | O31: =N31-K31 -> 108315.55 | P31: =IF(H31+G31>F31,"CHECK: Sold+Loss > Harvest","OK") -> OK | Q31: =INDEX(Crops!$B$2:$B$7,MATCH(D31,Crops!$A$2:$A$7,0)) -> Pepper | R31: =INDEX(Districts!$B$2:$B$6,MATCH(C31,Districts!$A$2:$A$6,0)) -> Tamale Metro | T31: Soybean | U31: =SUMIFS($O$2:$O$501,$D$2:$D$501,"C05") -> 3278962.5 | V31: =(U15 - U21) / U15 -> 0.79989219
A32: F0114 | B32: 46201 | C32: D01 | D32: C06 | E32: 4.7 | F32: 32979.9 | G32: 1452.6 | H32: 31527.3 | I32: Processor | J32: 2.73 | K32: 3441.09 | L32: =F32/E32 -> 7017 | M32: =G32/F32 -> 0.044045009 | N32: =H32*J32 -> 86069.529 | O32: =N32-K32 -> 82628.439 | P32: =IF(H32+G32>F32,"CHECK: Sold+Loss > Harvest","OK") -> OK | Q32: =INDEX(Crops!$B$2:$B$7,MATCH(D32,Crops!$A$2:$A$7,0)) -> Cassava | R32: =INDEX(Districts!$B$2:$B$6,MATCH(C32,Districts!$A$2:$A$6,0)) -> Ejura | T32: Maize | U32: =SUMIFS($O$2:$O$501,$D$2:$D$501,"C01") -> 2454054.1 | V32: =(U16 - U22) / U16 -> 0.76445377
A33: F0140 | B33: 45857 | C33: D01 | D33: C06 | E33: 7.8 | F33: 35529.2 | G33: 2377.6 | H33: 33151.6 | I33: Processor | J33: 2.54 | K33: 11431.77 | L33: =F33/E33 -> 4555.0256 | M33: =G33/F33 -> 0.066919604 | N33: =H33*J33 -> 84205.064 | O33: =N33-K33 -> 72773.294 | P33: =IF(H33+G33>F33,"CHECK: Sold+Loss > Harvest","OK") -> OK | Q33: =INDEX(Crops!$B$2:$B$7,MATCH(D33,Crops!$A$2:$A$7,0)) -> Cassava | R33: =INDEX(Districts!$B$2:$B$6,MATCH(C33,Districts!$A$2:$A$6,0)) -> Ejura
A34: F0057 | B34: 46011 | C34: D05 | D34: C05 | E34: 10.3 | F34: 13728.5 | G34: 434.1 | H34: 13294.4 | I34: Farm Gate | J34: 5.23 | K34: 12199.7 | L34: =F34/E34 -> 1332.8641 | M34: =G34/F34 -> 0.031620352 | N34: =H34*J34 -> 69529.712 | O34: =N34-K34 -> 57330.012 | P34: =IF(H34+G34>F34,"CHECK: Sold+Loss > Harvest","OK") -> OK | Q34: =INDEX(Crops!$B$2:$B$7,MATCH(D34,Crops!$A$2:$A$7,0)) -> Soybean | R34: =INDEX(Districts!$B$2:$B$6,MATCH(C34,Districts!$A$2:$A$6,0)) -> Hohoe
A35: F0205 | B35: 46026 | C35: D03 | D35: C06 | E35: 8.1 | F35: 32729.6 | G35: 1801.9 | H35: 30927.7 | I35: Farm Gate | J35: 2.19 | K35: 6146.74 | L35: =F35/E35 -> 4040.6914 | M35: =G35/F35 -> 0.055054141 | N35: =H35*J35 -> 67731.663 | O35: =N35-K35 -> 61584.923 | P35: =IF(H35+G35>F35,"CHECK: Sold+Loss > Harvest","OK") -> OK | Q35: =INDEX(Crops!$B$2:$B$7,MATCH(D35,Crops!$A$2:$A$7,0)) -> Cassava | R35: =INDEX(Districts!$B$2:$B$6,MATCH(C35,Districts!$A$2:$A$6,0)) -> Tamale Metro
A36: F0107 | B36: 45845 | C36: D04 | D36: C02 | E36: 5 | F36: 9246.7 | G36: 711 | H36: 8535.7 | I36: Farm Gate | J36: 5.25 | K36: 8339.42 | L36: =F36/E36 -> 1849.34 | M36: =G36/F36 -> 0.076892297 | N36: =H36*J36 -> 44812.425 | O36: =N36-K36 -> 36473.005 | P36: =IF(H36+G36>F36,"CHECK: Sold+Loss > Harvest","OK") -> OK | Q36: =INDEX(Crops!$B$2:$B$7,MATCH(D36,Crops!$A$2:$A$7,0)) -> Rice | R36: =INDEX(Districts!$B$2:$B$6,MATCH(C36,Districts!$A$2:$A$6,0)) -> Kintampo
A37: F0147 | B37: 45885 | C37: D04 | D37: C05 | E37: 10.3 | F37: 19790.1 | G37: 1470.3 | H37: 18319.8 | I37: Processor | J37: 4.36 | K37: 15824.81 | L37: =F37/E37 -> 1921.3689 | M37: =G37/F37 -> 0.074294723 | N37: =H37*J37 -> 79874.328 | O37: =N37-K37 -> 64049.518 | P37: =IF(H37+G37>F37,"CHECK: Sold+Loss > Harvest","OK") -> OK | Q37: =INDEX(Crops!$B$2:$B$7,MATCH(D37,Crops!$A$2:$A$7,0)) -> Soybean | R37: =INDEX(Districts!$B$2:$B$6,MATCH(C37,Districts!$A$2:$A$6,0)) -> Kintampo
A38: F0181 | B38: 45945 | C38: D01 | D38: C05 | E38: 11.9 | F38: 12507.4 | G38: 556.8 | H38: 11950.6 | I38: Local Market | J38: 5.12 | K38: 8108.69 | L38: =F38/E38 -> 1051.042 | M38: =G38/F38 -> 0.044517646 | N38: =H38*J38 -> 61187.072 | O38: =N38-K38 -> 53078.382 | P38: =IF(H38+G38>F38,"CHECK: Sold+Loss > Harvest","OK") -> OK | Q38: =INDEX(Crops!$B$2:$B$7,MATCH(D38,Crops!$A$2:$A$7,0)) -> Soybean | R38: =INDEX(Districts!$B$2:$B$6,MATCH(C38,Districts!$A$2:$A$6,0)) -> Ejura
A39: F0188 | B39: 45878 | C39: D04 | D39: C01 | E39: 12 | F39: 15728.1 | G39: 1013.9 | H39: 14714.2 | I39: Processor | J39: 2.73 | K39: 15109.5 | L39: =F39/E39 -> 1310.675 | M39: =G39/F39 -> 0.064464239 | N39: =H39*J39 -> 40169.766 | O39: =N39-K39 -> 25060.266 | P39: =IF(H39+G39>F39,"CHECK: Sold+Loss > Harvest","OK") -> OK | Q39: =INDEX(Crops!$B$2:$B$7,MATCH(D39,Crops!$A$2:$A$7,0)) -> Maize | R39: =INDEX(Districts!$B$2:$B$6,MATCH(C39,Districts!$A$2:$A$6,0)) -> Kintampo
A40: F0073 | B40: 45950 | C40: D02 | D40: C01 | E40: 13.4 | F40: 23211.6 | G40: 2893.1 | H40: 20318.5 | I40: Processor | J40: 2.95 | K40: 20095.44 | L40: =F40/E40 -> 1732.209 | M40: =G40/F40 -> 0.12464027 | N40: =H40*J40 -> 59939.575 | O40: =N40-K40 -> 39844.135 | P40: =IF(H40+G40>F40,"CHECK: Sold+Loss > Harvest","OK") -> OK | Q40: =INDEX(Crops!$B$2:$B$7,MATCH(D40,Crops!$A$2:$A$7,0)) -> Maize | R40: =INDEX(Districts!$B$2:$B$6,MATCH(C40,Districts!$A$2:$A$6,0)) -> Techiman
...

Sheet Pivot
A3: Row Labels | B3: Sum of Gross Margin (GHS) | C3: Sum of Revenue (GHS)
A4: Tomato | B4: 34941695 | C4: 35966209
A5: Pepper | B5: 22972066 | C5: 23685224
A6: Rice | B6: 8368911.2 | C6: 9296537
A7: Cassava | B7: 7574519.4 | C7: 8291839.4
A8: Soybean | B8: 3278962.5 | C8: 4099255.6
A9: Maize | B9: 2454054.1 | C9: 3210206.1
A10: Grand Total | B10: 79590209 | C10: 84549272
B23: Margin Concentration Across Crops and Districts
B26: Concentration reflects planted acreage more than farming efficiency
A29: Sum of Gross Margin (GHS) | B29: Column Labels
A30: Row Labels | B30: Ejura | C30: Hohoe | D30: Kintampo | E30: Tamale Metro | F30: Techiman | G30: Grand Total
A31: Cassava | B31: 1774028.6 | C31: 1677267.1 | D31: 1213890.6 | E31: 1187733.8 | F31: 1721599.2 | G31: 7574519.4
A32: Maize | B32: 555403.72 | C32: 628495.44 | D32: 419478.07 | E32: 507515.04 | F32: 343161.85 | G32: 2454054.1
A33: Pepper | B33: 4104242.9 | C33: 4831071.9 | D33: 5409257.5 | E33: 5483754.3 | F33: 3143739.3 | G33: 22972066
A34: Rice | B34: 1512444.3 | C34: 2071210.7 | D34: 2435208.2 | E34: 1482025.1 | F34: 868022.96 | G34: 8368911.2
A35: Soybean | B35: 636142.18 | C35: 777595.34 | D35: 772065.21 | E35: 678657.24 | F35: 414502.57 | G35: 3278962.5
A36: Tomato | B36: 7231056.5 | C36: 7753969.1 | D36: 4047738.3 | E36: 9060742.6 | F36: 6848188.9 | G36: 34941695
A37: Grand Total | B37: 15813318 | C37: 17739609 | D37: 14297638 | E37: 18400428 | F37: 13339215 | G37: 79590209
